from datetime import datetime, timedelta
from typing import Optional
from jose import JWTError, jwt
from passlib.context import CryptContext
from fastapi import Depends, HTTPException, status
from fastapi.security import OAuth2PasswordBearer
from sqlalchemy.ext.asyncio import AsyncSession
from sqlalchemy.future import select
from .database import get_db
from .models import User
import os
from dotenv import load_dotenv

load_dotenv()

# Constants
SECRET_KEY = os.getenv("JWT_SECRET", "dev_secret_key_replace_in_production")
ALGORITHM = "HS256"
ACCESS_TOKEN_EXPIRE_MINUTES = 30

pwd_context = CryptContext(schemes=["bcrypt"], deprecated="auto")
oauth2_scheme = OAuth2PasswordBearer(tokenUrl="api/login")

def verify_password(plain_password: str, hashed_password: str) -> bool:
    try:
        return pwd_context.verify(plain_password, hashed_password)
    except Exception:
        return False

def get_password_hash(password: str) -> str:
    return pwd_context.hash(password)

def create_access_token(data: dict, expires_delta: Optional[timedelta] = None) -> str:
    to_encode = data.copy()
    expire = datetime.utcnow() + (expires_delta or timedelta(minutes=ACCESS_TOKEN_EXPIRE_MINUTES))
    to_encode.update({"exp": expire})
    return jwt.encode(to_encode, SECRET_KEY, algorithm=ALGORITHM)

async def get_current_user(token: str = Depends(oauth2_scheme), db: AsyncSession = Depends(get_db)) -> User:
    credentials_exception = HTTPException(
        status_code=status.HTTP_401_UNAUTHORIZED,
        detail="Could not validate credentials",
        headers={"WWW-Authenticate": "Bearer"},
    )
    try:
        payload = jwt.decode(token, SECRET_KEY, algorithms=[ALGORITHM])
        user_id: str = payload.get("sub")
        if user_id is None:
            raise credentials_exception
    except JWTError:
        raise credentials_exception
        
    async with db as session:
        result = await session.execute(select(User).filter(User.id == int(user_id)))
        user = result.scalar_one_or_none()
        
    if user is None:
        raise credentials_exception
    return user
